{"nbformat":4,"nbformat_minor":0,"metadata":{"colab":{"name":"Классификация последовательностей с помощью LSTM:.ipynb","provenance":[],"collapsed_sections":[],"authorship_tag":"ABX9TyOiUHw6Rh8X0G5XLBqsOD6U"},"kernelspec":{"name":"python3","display_name":"Python 3"},"language_info":{"name":"python"}},"cells":[{"cell_type":"code","execution_count":5,"metadata":{"colab":{"base_uri":"https://localhost:8080/","height":817},"id":"WSzaU_rVaGME","executionInfo":{"status":"error","timestamp":1656572999371,"user_tz":-180,"elapsed":773,"user":{"displayName":"ILYA KOROTKIKH","userId":"04037128125645196318"}},"outputId":"39c11bf9-1f2c-4961-e8d0-3e84bb418eaa"},"outputs":[{"output_type":"stream","name":"stdout","text":["Epoch 1/10\n","WARNING:tensorflow:Model was constructed with shape (None, None) for input KerasTensor(type_spec=TensorSpec(shape=(None, None), dtype=tf.float32, name='embedding_1_input'), name='embedding_1_input', description=\"created by layer 'embedding_1_input'\"), but it was called on an input with incompatible shape (None, 100, 100, 3).\n"]},{"output_type":"error","ename":"ValueError","evalue":"ignored","traceback":["\u001b[0;31m---------------------------------------------------------------------------\u001b[0m","\u001b[0;31mValueError\u001b[0m                                Traceback (most recent call last)","\u001b[0;32m<ipython-input-5-e52a64036274>\u001b[0m in \u001b[0;36m<module>\u001b[0;34m()\u001b[0m\n\u001b[1;32m     36\u001b[0m               metrics=['accuracy'])\n\u001b[1;32m     37\u001b[0m \u001b[0;34m\u001b[0m\u001b[0m\n\u001b[0;32m---> 38\u001b[0;31m \u001b[0mmodel\u001b[0m\u001b[0;34m.\u001b[0m\u001b[0mfit\u001b[0m\u001b[0;34m(\u001b[0m\u001b[0mx_train\u001b[0m\u001b[0;34m,\u001b[0m \u001b[0my_train\u001b[0m\u001b[0;34m,\u001b[0m \u001b[0mbatch_size\u001b[0m\u001b[0;34m=\u001b[0m\u001b[0;36m16\u001b[0m\u001b[0;34m,\u001b[0m \u001b[0mepochs\u001b[0m\u001b[0;34m=\u001b[0m\u001b[0;36m10\u001b[0m\u001b[0;34m)\u001b[0m\u001b[0;34m\u001b[0m\u001b[0;34m\u001b[0m\u001b[0m\n\u001b[0m\u001b[1;32m     39\u001b[0m \u001b[0;34m\u001b[0m\u001b[0m\n\u001b[1;32m     40\u001b[0m \u001b[0mscore\u001b[0m \u001b[0;34m=\u001b[0m \u001b[0mmodel\u001b[0m\u001b[0;34m.\u001b[0m\u001b[0mevaluate\u001b[0m\u001b[0;34m(\u001b[0m\u001b[0mx_test\u001b[0m\u001b[0;34m,\u001b[0m \u001b[0my_test\u001b[0m\u001b[0;34m,\u001b[0m \u001b[0mbatch_size\u001b[0m\u001b[0;34m=\u001b[0m\u001b[0;36m16\u001b[0m\u001b[0;34m)\u001b[0m\u001b[0;34m\u001b[0m\u001b[0;34m\u001b[0m\u001b[0m\n","\u001b[0;32m/usr/local/lib/python3.7/dist-packages/keras/utils/traceback_utils.py\u001b[0m in \u001b[0;36merror_handler\u001b[0;34m(*args, **kwargs)\u001b[0m\n\u001b[1;32m     65\u001b[0m     \u001b[0;32mexcept\u001b[0m \u001b[0mException\u001b[0m \u001b[0;32mas\u001b[0m \u001b[0me\u001b[0m\u001b[0;34m:\u001b[0m  \u001b[0;31m# pylint: disable=broad-except\u001b[0m\u001b[0;34m\u001b[0m\u001b[0;34m\u001b[0m\u001b[0m\n\u001b[1;32m     66\u001b[0m       \u001b[0mfiltered_tb\u001b[0m \u001b[0;34m=\u001b[0m \u001b[0m_process_traceback_frames\u001b[0m\u001b[0;34m(\u001b[0m\u001b[0me\u001b[0m\u001b[0;34m.\u001b[0m\u001b[0m__traceback__\u001b[0m\u001b[0;34m)\u001b[0m\u001b[0;34m\u001b[0m\u001b[0;34m\u001b[0m\u001b[0m\n\u001b[0;32m---> 67\u001b[0;31m       \u001b[0;32mraise\u001b[0m \u001b[0me\u001b[0m\u001b[0;34m.\u001b[0m\u001b[0mwith_traceback\u001b[0m\u001b[0;34m(\u001b[0m\u001b[0mfiltered_tb\u001b[0m\u001b[0;34m)\u001b[0m \u001b[0;32mfrom\u001b[0m \u001b[0;32mNone\u001b[0m\u001b[0;34m\u001b[0m\u001b[0;34m\u001b[0m\u001b[0m\n\u001b[0m\u001b[1;32m     68\u001b[0m     \u001b[0;32mfinally\u001b[0m\u001b[0;34m:\u001b[0m\u001b[0;34m\u001b[0m\u001b[0;34m\u001b[0m\u001b[0m\n\u001b[1;32m     69\u001b[0m       \u001b[0;32mdel\u001b[0m \u001b[0mfiltered_tb\u001b[0m\u001b[0;34m\u001b[0m\u001b[0;34m\u001b[0m\u001b[0m\n","\u001b[0;32m/usr/local/lib/python3.7/dist-packages/tensorflow/python/framework/func_graph.py\u001b[0m in \u001b[0;36mautograph_handler\u001b[0;34m(*args, **kwargs)\u001b[0m\n\u001b[1;32m   1145\u001b[0m           \u001b[0;32mexcept\u001b[0m \u001b[0mException\u001b[0m \u001b[0;32mas\u001b[0m \u001b[0me\u001b[0m\u001b[0;34m:\u001b[0m  \u001b[0;31m# pylint:disable=broad-except\u001b[0m\u001b[0;34m\u001b[0m\u001b[0;34m\u001b[0m\u001b[0m\n\u001b[1;32m   1146\u001b[0m             \u001b[0;32mif\u001b[0m \u001b[0mhasattr\u001b[0m\u001b[0;34m(\u001b[0m\u001b[0me\u001b[0m\u001b[0;34m,\u001b[0m \u001b[0;34m\"ag_error_metadata\"\u001b[0m\u001b[0;34m)\u001b[0m\u001b[0;34m:\u001b[0m\u001b[0;34m\u001b[0m\u001b[0;34m\u001b[0m\u001b[0m\n\u001b[0;32m-> 1147\u001b[0;31m               \u001b[0;32mraise\u001b[0m \u001b[0me\u001b[0m\u001b[0;34m.\u001b[0m\u001b[0mag_error_metadata\u001b[0m\u001b[0;34m.\u001b[0m\u001b[0mto_exception\u001b[0m\u001b[0;34m(\u001b[0m\u001b[0me\u001b[0m\u001b[0;34m)\u001b[0m\u001b[0;34m\u001b[0m\u001b[0;34m\u001b[0m\u001b[0m\n\u001b[0m\u001b[1;32m   1148\u001b[0m             \u001b[0;32melse\u001b[0m\u001b[0;34m:\u001b[0m\u001b[0;34m\u001b[0m\u001b[0;34m\u001b[0m\u001b[0m\n\u001b[1;32m   1149\u001b[0m               \u001b[0;32mraise\u001b[0m\u001b[0;34m\u001b[0m\u001b[0;34m\u001b[0m\u001b[0m\n","\u001b[0;31mValueError\u001b[0m: in user code:\n\n    File \"/usr/local/lib/python3.7/dist-packages/keras/engine/training.py\", line 1021, in train_function  *\n        return step_function(self, iterator)\n    File \"/usr/local/lib/python3.7/dist-packages/keras/engine/training.py\", line 1010, in step_function  **\n        outputs = model.distribute_strategy.run(run_step, args=(data,))\n    File \"/usr/local/lib/python3.7/dist-packages/keras/engine/training.py\", line 1000, in run_step  **\n        outputs = model.train_step(data)\n    File \"/usr/local/lib/python3.7/dist-packages/keras/engine/training.py\", line 859, in train_step\n        y_pred = self(x, training=True)\n    File \"/usr/local/lib/python3.7/dist-packages/keras/utils/traceback_utils.py\", line 67, in error_handler\n        raise e.with_traceback(filtered_tb) from None\n    File \"/usr/local/lib/python3.7/dist-packages/keras/engine/input_spec.py\", line 214, in assert_input_compatibility\n        raise ValueError(f'Input {input_index} of layer \"{layer_name}\" '\n\n    ValueError: Exception encountered when calling layer \"sequential_1\" (type Sequential).\n    \n    Input 0 of layer \"lstm_1\" is incompatible with the layer: expected ndim=3, found ndim=5. Full shape received: (None, 100, 100, 3, 256)\n    \n    Call arguments received:\n      • inputs=tf.Tensor(shape=(None, 100, 100, 3), dtype=float32)\n      • training=True\n      • mask=None\n"]}],"source":["from keras.models import Sequential\n","\n","from keras.layers import Dense, Dropout\n","\n","from keras.layers import Embedding\n","import keras\n","from keras.layers import LSTM\n","import numpy as np\n","max_features = 1024\n","\n","\n","x_train = np.random.random((100, 100, 100, 3))\n","\n","y_train = keras.utils.np_utils.to_categorical(\n","np.random.randint(10, size=(100, 1)), num_classes=10)\n","\n","x_test = np.random.random((20, 100, 100, 3))\n","\n","y_test = keras.utils.np_utils.to_categorical(\n","np.random.randint(10, size=(20, 1)), num_classes=10)\n","\n","model = Sequential()\n","\n","model.add(Embedding(max_features, output_dim=256))\n","\n","model.add(LSTM(128))\n","\n","model.add(Dropout(0.5))\n","\n","model.add(Dense(1, activation='sigmoid'))\n","\n","model.compile(loss='binary_crossentropy',\n","\n","              optimizer='rmsprop',\n","\n","              metrics=['accuracy'])\n","\n","model.fit(x_train, y_train, batch_size=16, epochs=10)\n","\n","score = model.evaluate(x_test, y_test, batch_size=16)"]}]}